Workbook

Sheet Sheet1
A1: Invoice | B1: StockCode | C1: Description | D1: Quantity | E1: InvoiceDate | F1: Price | G1: Customer ID | H1: Country
A2: 503181 | B2: 84792 | C2: ENCHANTED BIRD COATHANGER 5 HOOK | D2: 4 | E2: 40267.599 | F2: 4.65 | H2: United Kingdom
A3: 528386 | B3: 22318 | C3: FIVE HEART HANGING DECORATION | D3: 6 | E3: 40472.772 | F3: 2.95 | G3: 14911 | H3: EIRE
A4: 498594 | B4: 21173 | C4: LOO ROLL METAL SIGN | D4: 1 | E4: 40230.658 | F4: 1.65 | G4: 16797 | H4: United Kingdom
A5: 503245 | B5: 21777 | C5: RECIPE BOX WITH METAL HEART | D5: 2 | E5: 40268.411 | F5: 7.95 | G5: 15216 | H5: United Kingdom
A6: 505756 | B6: 84836 | C6: ZINC METAL HEART DECORATION | D6: 12 | E6: 40294.408 | F6: 1.25 | G6: 14677 | H6: United Kingdom
A7: 496975 | B7: 21559 | C7: STRAWBERRY LUNCHBOX WITH CUTLERY | D7: 6 | E7: 40214.385 | F7: 2.55 | G7: 12712 | H7: Germany
A8: 491584 | B8: 85107 | C8: CUT GLASS T-LIGHT HOLDER OCTAGON | D8: 12 | E8: 40158.538 | F8: 2.55 | G8: 12854 | H8: United Kingdom
A9: 516478 | B9: 22575 | C9: METAL MERRY CHRISTMAS WREATH | D9: 1 | E9: 40379.722 | F9: 1.95 | G9: 17576 | H9: United Kingdom
A10: 502588 | B10: 22083 | C10: PAPER CHAIN KIT RETRO SPOT | D10: 2 | E10: 40262.53 | F10: 2.95 | G10: 16550 | H10: United Kingdom
A11: 515335 | B11: 85014B | C11: RED/WHITE DOTS RUFFLED UMBRELLA | D11: 1 | E11: 40370.597 | F11: 5.95 | G11: 14606 | H11: United Kingdom
A12: 525065 | B12: 21156 | C12: RETROSPOT CHILDRENS APRON | D12: 1 | E12: 40454.603 | F12: 1.95 | G12: 16799 | H12: United Kingdom
A13: 535349 | B13: 84946 | C13: ANTIQUE SILVER TEA GLASS ETCHED | D13: 24 | E13: 40507.703 | F13: 1.25 | G13: 18245 | H13: United Kingdom
A14: 521949 | B14: 82484 | C14: WOOD BLACK BOARD ANT WHITE FINISH | D14: 3 | E14: 40430.719 | F14: 6.45 | G14: 15150 | H14: United Kingdom
A15: 514876 | B15: 22519 | C15: CHILDS GARDEN BRUSH PINK | D15: 36 | E15: 40366.44 | F15: 1.85 | G15: 17511 | H15: United Kingdom
A16: 521162 | B16: 22561 | C16: WOODEN SCHOOL COLOURING SET | D16: 12 | E16: 40423.599 | F16: 1.65 | G16: 12598 | H16: France
A17: 506572 | B17: 20798 | C17: CLEAR MILKSHAKE GLASS | D17: 4 | E17: 40298.549 | F17: 2.1 | G17: 16374 | H17: United Kingdom
A18: 505974 | B18: 48188 | C18: DOOR MAT WELCOME PUPPIES | D18: 1 | E18: 40294.754 | F18: 7.49 | G18: 17449 | H18: United Kingdom
A19: 491622 | B19: 10125 | C19: MINI FUNKY DESIGN TAPES | D19: 1 | E19: 40158.597 | F19: 0.85 | G19: 13415 | H19: U.K.
A20: 509982 | B20: 21696 | C20: SMALL SILVER TRELLIS CANDLEPOT | D20: 6 | E20: 40324.603 | F20: 2.95 | G20: 12924 | H20: United Kingdom
A21: 524611 | B21: 85114B | C21: IVORY ENCHANTED FOREST PLACEMAT | D21: 6 | E21: 40451.401 | F21: 1.65 | G21: 13078 | H21: United Kingdom
A22: 501906 | B22: 22413 | C22: METAL SIGN TAKE IT OR LEAVE IT | D22: 12 | E22: 40258.668 | F22: 2.95 | G22: 17340 | H22: United Kingdom
A23: 505708 | B23: 20979 | C23: 36 PENCILS TUBE RED SPOTTY | D23: 1 | E23: 40293.51 | F23: 1.25 | G23: 13782 | H23: United Kingdom
A24: 497935 | B24: 79323W | C24: WHITE CHERRY LIGHTS | D24: 24 | E24: 40224.449 | F24: 5.45 | G24: 13408 | H24: United Kingdom
A25: 502792 | B25: 15044C | C25: PURPLE PAPER PARASOL | D25: 6 | E25: 40263.631 | F25: 2.95 | G25: 14253 | H25: United Kingdom
A26: 521403 | B26: 21179 | D26: 12 | E26: 40427.43 | F26: 1.25 | G26: 12744 | H26: Singapore
A27: 522904 | B27: 72529W | C27: WHITE ADVENT CANDLE | D27: 1 | E27: 40438.531 | F27: 2.12 | G27: 17765 | H27: United Kingdom
A28: 537810 | B28: 22415 | C28: WHITE TISSUE REAM | D28: 3 | E28: 08-12-2010 13:30 | F28: 7.95 | G28: 15032 | H28: United Kingdom
A29: 520505 | B29: 21258 | C29: VICTORIAN SEWING BOX LARGE | D29: 1 | E29: 40416.535 | F29: 12.75 | G29: 17663 | H29: United Kingdom
A30: 533067 | B30: 21122 | C30: SET/10 PINK POLKADOT PARTY CANDLES | D30: 24 | E30: 40497.718 | F30: 1.25 | G30: 17284 | H30: United Kingdom
A31: 523971 | B31: 21009 | C31: ETCHED GLASS STAR TREE DECORATION | D31: 6 | E31: 40447.578 | F31: 1.25 | G31: 15967 | H31: United Kingdom
A32: 499625 | B32: 15056BL | C32: EDWARDIAN PARASOL BLACK | D32: 2 | E32: 40238.551 | F32: 5.95 | G32: 17965 | H32: United Kingdom
A33: 500147 | B33: 47566 | C33: PARTY BUNTING | D33: 8 | E33: 40241.724 | F33: 4.65 | G33: 15812 | H33: United Kingdom
A34: 537421 | B34: 22569 | C34: FELTCRAFT CUSHION BUTTERFLY | D34: 2 | E34: 40518.642 | F34: 3.75 | G34: 17218 | H34: UNITED KINGDOM
A35: 534526 | B35: 21930 | C35: JUMBO STORAGE BAG SKULLS | D35: 10 | E35: 40505.503 | F35: 1.95 | G35: 15384 | H35: United Kingdom
A36: 503164 | B36: 22556 | C36: PLASTERS IN TIN CIRCUS PARADE | D36: 1 | E36: 40267.552 | F36: 1.65 | G36: 17464 | H36: United Kingdom
A37: 528618 | B37: 21499 | C37: BLUE POLKADOT WRAP | D37: 25 | E37: 40473.713 | F37: 0.42 | G37: 13263 | H37: United Kingdom
A38: 505015 | B38: 22196 | C38: SMALL HEART MEASURING SPOONS | D38: 12 | E38: 40287.562 | F38: 0.85 | G38: 14156 | H38: EIRE
A39: 497272 | B39: 84510B | C39: SET OF 4 FAIRY CAKES COASTERS | D39: 10 | E39: 40217.576 | F39: 1.25 | G39: 17160 | H39: United Kingdom
A40: 518480 | B40: 21890 | C40: S/6 WOODEN SKITTLES IN COTTON BAG | D40: 2 | E40: 40399.515 | F40: 2.95 | G40: 16470 | H40: United Kingdom
...

Sheet Sheet2
A1: Customer ID | B1: StockCode | C1: Description | D1: Quantity | E1: Quantity | F1: Quantity | G1: Invoice | H1: InvoiceDate | I1: Price | J1: Price | K1: Invoice Date | N1: Invoice Time | O1: Country | P1: Revenue
A2: 14606 | B2: 84792 | C2: ENCHANTED BIRD COATHANGER 5 HOOK | D2: =ABS(E2) -> 4 | E2: =VALUE(F2) -> 4 | F2: 4 | G2: 503181 | H2: 40267.599 | I2: 4.65 | J2: =VALUE(I2) -> 4.65 | K2: 40267 | L2: 0.099305556 | M2: PM | N2: =TEXT(L2,"h:mm")&" "&M2 -> 2:23 PM | O2: United Kingdom | P2: =PRODUCT(D2,(J2)) -> 18.6
A3: 14911 | B3: 22318 | C3: FIVE HEART HANGING DECORATION | D3: =ABS(E3) -> 6 | E3: =VALUE(F3) -> 6 | F3: 6 | G3: 528386 | H3: 40472.772 | I3: 2.95 | J3: =VALUE(I3) -> 2.95 | K3: 40472 | L3: 0.27222222 | M3: PM | N3: =TEXT(L3,"h:mm")&" "&M3 -> 6:32 PM | O3: EIRE | P3: =PRODUCT(D3,(J3)) -> 17.7
A4: 16797 | B4: 21173 | C4: LOO ROLL METAL SIGN | D4: =ABS(E4) -> 1 | E4: =VALUE(F4) -> 1 | F4: 1 | G4: 498594 | H4: 40230.658 | I4: 1.65 | J4: =VALUE(I4) -> 1.65 | K4: 40230 | L4: 0.15833333 | M4: PM | N4: =TEXT(L4,"h:mm")&" "&M4 -> 3:48 PM | O4: United Kingdom | P4: =PRODUCT(D4,(J4)) -> 1.65
A5: 15216 | B5: 21777 | C5: RECIPE BOX WITH METAL HEART | D5: =ABS(E5) -> 2 | E5: =VALUE(F5) -> 2 | F5: 2 | G5: 503245 | H5: 40268.411 | I5: 7.95 | J5: =VALUE(I5) -> 7.95 | K5: 40268 | L5: 0.41111111 | M5: AM | N5: =TEXT(L5,"h:mm")&" "&M5 -> 9:52 AM | O5: United Kingdom | P5: =PRODUCT(D5,(J5)) -> 15.9
A6: 14677 | B6: 84836 | C6: ZINC METAL HEART DECORATION | D6: =ABS(E6) -> 12 | E6: =VALUE(F6) -> 12 | F6: 12 | G6: 505756 | H6: 40294.408 | I6: 1.25 | J6: =VALUE(I6) -> 1.25 | K6: 40294 | L6: 0.40833333 | M6: AM | N6: =TEXT(L6,"h:mm")&" "&M6 -> 9:48 AM | O6: United Kingdom | P6: =PRODUCT(D6,(J6)) -> 15
A7: 12712 | B7: 21559 | C7: STRAWBERRY LUNCHBOX WITH CUTLERY | D7: =ABS(E7) -> 6 | E7: =VALUE(F7) -> 6 | F7: 6 | G7: 496975 | H7: 40214.385 | I7: 2.55 | J7: =VALUE(I7) -> 2.55 | K7: 40214 | L7: 0.38472222 | M7: AM | N7: =TEXT(L7,"h:mm")&" "&M7 -> 9:14 AM | O7: Germany | P7: =PRODUCT(D7,(J7)) -> 15.3
A8: 12854 | B8: 85107 | C8: CUT GLASS T-LIGHT HOLDER OCTAGON | D8: =ABS(E8) -> 12 | E8: =VALUE(F8) -> 12 | F8: 12 | G8: 491584 | H8: 40158.538 | I8: 2.55 | J8: =VALUE(I8) -> 2.55 | K8: 40158 | L8: 0.53819444 | M8: PM | N8: =TEXT(L8,"h:mm")&" "&M8 -> 12:55 PM | O8: United Kingdom | P8: =PRODUCT(D8,(J8)) -> 30.6
A9: 17576 | B9: 22575 | C9: METAL MERRY CHRISTMAS WREATH | D9: =ABS(E9) -> 1 | E9: =VALUE(F9) -> 1 | F9: 1 | G9: 516478 | H9: 40379.722 | I9: 1.95 | J9: =VALUE(I9) -> 1.95 | K9: 40379 | L9: 0.22222222 | M9: PM | N9: =TEXT(L9,"h:mm")&" "&M9 -> 5:20 PM | O9: United Kingdom | P9: =PRODUCT(D9,(J9)) -> 1.95
A10: 16550 | B10: 22083 | C10: PAPER CHAIN KIT RETRO SPOT | D10: =ABS(E10) -> 2 | E10: =VALUE(F10) -> 2 | F10: 2 | G10: 502588 | H10: 40262.53 | I10: 2.95 | J10: =VALUE(I10) -> 2.95 | K10: 40262 | L10: 0.52986111 | M10: PM | N10: =TEXT(L10,"h:mm")&" "&M10 -> 12:43 PM | O10: United Kingdom | P10: =PRODUCT(D10,(J10)) -> 5.9
A11: 14606 | B11: 85014B | C11: RED/WHITE DOTS RUFFLED UMBRELLA | D11: =ABS(E11) -> 1 | E11: =VALUE(F11) -> 1 | F11: 1 | G11: 515335 | H11: 40370.597 | I11: 5.95 | J11: =VALUE(I11) -> 5.95 | K11: 40370 | L11: 0.096527778 | M11: PM | N11: =TEXT(L11,"h:mm")&" "&M11 -> 2:19 PM | O11: United Kingdom | P11: =PRODUCT(D11,(J11)) -> 5.95
A12: 16799 | B12: 21156 | C12: RETROSPOT CHILDRENS APRON | D12: =ABS(E12) -> 1 | E12: =VALUE(F12) -> 1 | F12: 1 | G12: 525065 | H12: 40454.603 | I12: 1.95 | J12: =VALUE(I12) -> 1.95 | K12: 40454 | L12: 0.10277778 | M12: PM | N12: =TEXT(L12,"h:mm")&" "&M12 -> 2:28 PM | O12: United Kingdom | P12: =PRODUCT(D12,(J12)) -> 1.95
A13: 18245 | B13: 84946 | C13: ANTIQUE SILVER TEA GLASS ETCHED | D13: =ABS(E13) -> 24 | E13: =VALUE(F13) -> 24 | F13: 24 | G13: 535349 | H13: 40507.703 | I13: 1.25 | J13: =VALUE(I13) -> 1.25 | K13: 40507 | L13: 0.20277778 | M13: PM | N13: =TEXT(L13,"h:mm")&" "&M13 -> 4:52 PM | O13: United Kingdom | P13: =PRODUCT(D13,(J13)) -> 30
A14: 15150 | B14: 82484 | C14: WOOD BLACK BOARD ANT WHITE FINISH | D14: =ABS(E14) -> 3 | E14: =VALUE(F14) -> 3 | F14: 3 | G14: 521949 | H14: 40430.719 | I14: 6.45 | J14: =VALUE(I14) -> 6.45 | K14: 40430 | L14: 0.21944444 | M14: PM | N14: =TEXT(L14,"h:mm")&" "&M14 -> 5:16 PM | O14: United Kingdom | P14: =PRODUCT(D14,(J14)) -> 19.35
A15: 17511 | B15: 22519 | C15: CHILDS GARDEN BRUSH PINK | D15: =ABS(E15) -> 36 | E15: =VALUE(F15) -> 36 | F15: 36 | G15: 514876 | H15: 40366.44 | I15: 1.85 | J15: =VALUE(I15) -> 1.85 | K15: 40366 | L15: 0.43958333 | M15: AM | N15: =TEXT(L15,"h:mm")&" "&M15 -> 10:33 AM | O15: United Kingdom | P15: =PRODUCT(D15,(J15)) -> 66.6
A16: 12598 | B16: 22561 | C16: WOODEN SCHOOL COLOURING SET | D16: =ABS(E16) -> 12 | E16: =VALUE(F16) -> 12 | F16: 12 | G16: 521162 | H16: 40423.599 | I16: 1.65 | J16: =VALUE(I16) -> 1.65 | K16: 40423 | L16: 0.098611111 | M16: PM | N16: =TEXT(L16,"h:mm")&" "&M16 -> 2:22 PM | O16: France | P16: =PRODUCT(D16,(J16)) -> 19.8
A17: 16374 | B17: 20798 | C17: CLEAR MILKSHAKE GLASS | D17: =ABS(E17) -> 4 | E17: =VALUE(F17) -> 4 | F17: 4 | G17: 506572 | H17: 40298.549 | I17: 2.1 | J17: =VALUE(I17) -> 2.1 | K17: 40298 | L17: 0.048611111 | M17: PM | N17: =TEXT(L17,"h:mm")&" "&M17 -> 1:10 PM | O17: United Kingdom | P17: =PRODUCT(D17,(J17)) -> 8.4
A18: 17449 | B18: 48188 | C18: DOOR MAT WELCOME PUPPIES | D18: =ABS(E18) -> 1 | E18: =VALUE(F18) -> 1 | F18: 1 | G18: 505974 | H18: 40294.754 | I18: 7.49 | J18: =VALUE(I18) -> 7.49 | K18: 40294 | L18: 0.25416667 | M18: PM | N18: =TEXT(L18,"h:mm")&" "&M18 -> 6:06 PM | O18: United Kingdom | P18: =PRODUCT(D18,(J18)) -> 7.49
A19: 13415 | B19: 10125 | C19: MINI FUNKY DESIGN TAPES | D19: =ABS(E19) -> 1 | E19: =VALUE(F19) -> 1 | F19: 1 | G19: 491622 | H19: 40158.597 | I19: 0.85 | J19: =VALUE(I19) -> 0.85 | K19: 40158 | L19: 0.097222222 | M19: PM | N19: =TEXT(L19,"h:mm")&" "&M19 -> 2:20 PM | O19: United Kingdom | P19: =PRODUCT(D19,(J19)) -> 0.85
A20: 12924 | B20: 21696 | C20: SMALL SILVER TRELLIS CANDLEPOT | D20: =ABS(E20) -> 6 | E20: =VALUE(F20) -> 6 | F20: 6 | G20: 509982 | H20: 40324.603 | I20: 2.95 | J20: =VALUE(I20) -> 2.95 | K20: 40324 | L20: 0.10277778 | M20: PM | N20: =TEXT(L20,"h:mm")&" "&M20 -> 2:28 PM | O20: United Kingdom | P20: =PRODUCT(D20,(J20)) -> 17.7
A21: 13078 | B21: 85114B | C21: IVORY ENCHANTED FOREST PLACEMAT | D21: =ABS(E21) -> 6 | E21: =VALUE(F21) -> 6 | F21: 6 | G21: 524611 | H21: 40451.401 | I21: 1.65 | J21: =VALUE(I21) -> 1.65 | K21: 40451 | L21: 0.40069444 | M21: AM | N21: =TEXT(L21,"h:mm")&" "&M21 -> 9:37 AM | O21: United Kingdom | P21: =PRODUCT(D21,(J21)) -> 9.9
A22: 17340 | B22: 22413 | C22: METAL SIGN TAKE IT OR LEAVE IT | D22: =ABS(E22) -> 12 | E22: =VALUE(F22) -> 12 | F22: 12 | G22: 501906 | H22: 40258.668 | I22: 2.95 | J22: =VALUE(I22) -> 2.95 | K22: 40258 | L22: 0.16805556 | M22: PM | N22: =TEXT(L22,"h:mm")&" "&M22 -> 4:02 PM | O22: United Kingdom | P22: =PRODUCT(D22,(J22)) -> 35.4
A23: 13782 | B23: 20979 | C23: 36 PENCILS TUBE RED SPOTTY | D23: =ABS(E23) -> 1 | E23: =VALUE(F23) -> 1 | F23: 1 | G23: 505708 | H23: 40293.51 | I23: 1.25 | J23: =VALUE(I23) -> 1.25 | K23: 40293 | L23: 0.51041667 | M23: PM | N23: =TEXT(L23,"h:mm")&" "&M23 -> 12:15 PM | O23: United Kingdom | P23: =PRODUCT(D23,(J23)) -> 1.25
A24: 13408 | B24: 79323W | C24: WHITE CHERRY LIGHTS | D24: =ABS(E24) -> 24 | E24: =VALUE(F24) -> 24 | F24: 24 | G24: 497935 | H24: 40224.449 | I24: 5.45 | J24: =VALUE(I24) -> 5.45 | K24: 40224 | L24: 0.44930556 | M24: AM | N24: =TEXT(L24,"h:mm")&" "&M24 -> 10:47 AM | O24: United Kingdom | P24: =PRODUCT(D24,(J24)) -> 130.8
A25: 14253 | B25: 15044C | C25: PURPLE PAPER PARASOL | D25: =ABS(E25) -> 6 | E25: =VALUE(F25) -> 6 | F25: 6 | G25: 502792 | H25: 40263.631 | I25: 2.95 | J25: =VALUE(I25) -> 2.95 | K25: 40263 | L25: 0.13055556 | M25: PM | N25: =TEXT(L25,"h:mm")&" "&M25 -> 3:08 PM | O25: United Kingdom | P25: =PRODUCT(D25,(J25)) -> 17.7
A26: 12744 | B26: 21179 | C26: N/A | D26: =ABS(E26) -> 12 | E26: =VALUE(F26) -> 12 | F26: 12 | G26: 521403 | H26: 40427.43 | I26: 1.25 | J26: =VALUE(I26) -> 1.25 | K26: 40427 | L26: 0.42986111 | M26: AM | N26: =TEXT(L26,"h:mm")&" "&M26 -> 10:19 AM | O26: Singapore | P26: =PRODUCT(D26,(J26)) -> 15
A27: 17765 | B27: 72529W | C27: WHITE ADVENT CANDLE | D27: =ABS(E27) -> 1 | E27: =VALUE(F27) -> 1 | F27: 1 | G27: 522904 | H27: 40438.531 | I27: 2.12 | J27: =VALUE(I27) -> 2.12 | K27: 40438 | L27: 0.53125 | M27: PM | N27: =TEXT(L27,"h:mm")&" "&M27 -> 12:45 PM | O27: United Kingdom | P27: =PRODUCT(D27,(J27)) -> 2.12
A28: 15032 | B28: 22415 | C28: WHITE TISSUE REAM | D28: =ABS(E28) -> 3 | E28: =VALUE(F28) -> 3 | F28: 3 | G28: 537810 | H28: 08-12-2010 13:30 | I28: 7.95 | J28: =VALUE(I28) -> 7.95 | K28: 40402 | L28: 0.5625 | N28: =TEXT(L28,"h:mm")&" "&M28 -> 13:30 | O28: United Kingdom | P28: =PRODUCT(D28,(J28)) -> 23.85
A29: 17663 | B29: 21258 | C29: VICTORIAN SEWING BOX LARGE | D29: =ABS(E29) -> 1 | E29: =VALUE(F29) -> 1 | F29: 1 | G29: 520505 | H29: 40416.535 | I29: 12.75 | J29: =VALUE(I29) -> 12.75 | K29: 40416 | L29: 0.53541667 | M29: PM | N29: =TEXT(L29,"h:mm")&" "&M29 -> 12:51 PM | O29: United Kingdom | P29: =PRODUCT(D29,(J29)) -> 12.75
A30: 17284 | B30: 21122 | C30: SET/10 PINK POLKADOT PARTY CANDLES | D30: =ABS(E30) -> 24 | E30: =VALUE(F30) -> 24 | F30: 24 | G30: 533067 | H30: 40497.718 | I30: 1.25 | J30: =VALUE(I30) -> 1.25 | K30: 40497 | L30: 0.21805556 | M30: PM | N30: =TEXT(L30,"h:mm")&" "&M30 -> 5:14 PM | O30: United Kingdom | P30: =PRODUCT(D30,(J30)) -> 30
A31: 15967 | B31: 21009 | C31: ETCHED GLASS STAR TREE DECORATION | D31: =ABS(E31) -> 6 | E31: =VALUE(F31) -> 6 | F31: 6 | G31: 523971 | H31: 40447.578 | I31: 1.25 | J31: =VALUE(I31) -> 1.25 | K31: 40447 | L31: 0.078472222 | M31: PM | N31: =TEXT(L31,"h:mm")&" "&M31 -> 1:53 PM | O31: United Kingdom | P31: =PRODUCT(D31,(J31)) -> 7.5
A32: 17965 | B32: 15056BL | C32: EDWARDIAN PARASOL BLACK | D32: =ABS(E32) -> 2 | E32: =VALUE(F32) -> 2 | F32: 2 | G32: 499625 | H32: 40238.551 | I32: 5.95 | J32: =VALUE(I32) -> 5.95 | K32: 40238 | L32: 0.051388889 | M32: PM | N32: =TEXT(L32,"h:mm")&" "&M32 -> 1:14 PM | O32: United Kingdom | P32: =PRODUCT(D32,(J32)) -> 11.9
A33: 15812 | B33: 47566 | C33: PARTY BUNTING | D33: =ABS(E33) -> 8 | E33: =VALUE(F33) -> 8 | F33: 8 | G33: 500147 | H33: 40241.724 | I33: 4.65 | J33: =VALUE(I33) -> 4.65 | K33: 40241 | L33: 0.22361111 | M33: PM | N33: =TEXT(L33,"h:mm")&" "&M33 -> 5:22 PM | O33: United Kingdom | P33: =PRODUCT(D33,(J33)) -> 37.2
A34: 17218 | B34: 22569 | C34: FELTCRAFT CUSHION BUTTERFLY | D34: =ABS(E34) -> 2 | E34: =VALUE(F34) -> 2 | F34: 2 | G34: 537421 | H34: 40518.642 | I34: 3.75 | J34: =VALUE(I34) -> 3.75 | K34: 40518 | L34: 0.14236111 | M34: PM | N34: =TEXT(L34,"h:mm")&" "&M34 -> 3:25 PM | O34: United Kingdom | P34: =PRODUCT(D34,(J34)) -> 7.5
A35: 15384 | B35: 21930 | C35: JUMBO STORAGE BAG SKULLS | D35: =ABS(E35) -> 10 | E35: =VALUE(F35) -> 10 | F35: 10 | G35: 534526 | H35: 40505.503 | I35: 1.95 | J35: =VALUE(I35) -> 1.95 | K35: 40505 | L35: 0.50277778 | M35: PM | N35: =TEXT(L35,"h:mm")&" "&M35 -> 12:04 PM | O35: United Kingdom | P35: =PRODUCT(D35,(J35)) -> 19.5
A36: 17464 | B36: 22556 | C36: PLASTERS IN TIN CIRCUS PARADE | D36: =ABS(E36) -> 1 | E36: =VALUE(F36) -> 1 | F36: 1 | G36: 503164 | H36: 40267.552 | I36: 1.65 | J36: =VALUE(I36) -> 1.65 | K36: 40267 | L36: 0.052083333 | M36: PM | N36: =TEXT(L36,"h:mm")&" "&M36 -> 1:15 PM | O36: United Kingdom | P36: =PRODUCT(D36,(J36)) -> 1.65
A37: 13263 | B37: 21499 | C37: BLUE POLKADOT WRAP | D37: =ABS(E37) -> 25 | E37: =VALUE(F37) -> 25 | F37: 25 | G37: 528618 | H37: 40473.713 | I37: 0.42 | J37: =VALUE(I37) -> 0.42 | K37: 40473 | L37: 0.21319444 | M37: PM | N37: =TEXT(L37,"h:mm")&" "&M37 -> 5:07 PM | O37: United Kingdom | P37: =PRODUCT(D37,(J37)) -> 10.5
A38: 14156 | B38: 22196 | C38: SMALL HEART MEASURING SPOONS | D38: =ABS(E38) -> 12 | E38: =VALUE(F38) -> 12 | F38: 12 | G38: 505015 | H38: 40287.562 | I38: 0.85 | J38: =VALUE(I38) -> 0.85 | K38: 40287 | L38: 0.0625 | M38: PM | N38: =TEXT(L38,"h:mm")&" "&M38 -> 1:30 PM | O38: EIRE | P38: =PRODUCT(D38,(J38)) -> 10.2
A39: 17160 | B39: 84510B | C39: SET OF 4 FAIRY CAKES COASTERS | D39: =ABS(E39) -> 10 | E39: =VALUE(F39) -> 10 | F39: 10 | G39: 497272 | H39: 40217.576 | I39: 1.25 | J39: =VALUE(I39) -> 1.25 | K39: 40217 | L39: 0.076388889 | M39: PM | N39: =TEXT(L39,"h:mm")&" "&M39 -> 1:50 PM | O39: United Kingdom | P39: =PRODUCT(D39,(J39)) -> 12.5
A40: 16470 | B40: 21890 | C40: S/6 WOODEN SKITTLES IN COTTON BAG | D40: =ABS(E40) -> 2 | E40: =VALUE(F40) -> 2 | F40: 2 | G40: 518480 | H40: 40399.515 | I40: 2.95 | J40: =VALUE(I40) -> 2.95 | K40: 40399 | L40: 0.51458333 | M40: PM | N40: =TEXT(L40,"h:mm")&" "&M40 -> 12:21 PM | O40: United Kingdom | P40: =PRODUCT(D40,(J40)) -> 5.9
...

Sheet Sheet3
A1: Issue Found | B1: column | C1: Action Taken | D1: Result
A2: Arrangement of columns | B2: Invoice, Customer ID | C2: Rearrnage the columns | D2: Columns arranged
A3: inconsistent text formatting | B3: Country | C3: Formatted text | D3: Consistent text format
A4: Duplicates | B4: country | C4: Remove duplicates | D4: duplicates removed
A5: Missing values | B5: Description, quantity, price, customer ID and country, | C5: Reviewed and documented | D5: Missing Values handled
A6: Data types | B6: All columns | C6: Reviewed and corrected data types | D6: Data types corected
A7: Date and Time were combined | B7: Invoice date | C7: Separated date and time into two different columns | D7: Date and time now in different columns
A8: Some numbers were stored as text | B8: Stock code, quantity and Price | C8: Corrrected the affected cells to their correct data types | D8: Affected cells were standardized to its correct data types
A9: Negative Value | B9: Quantity | C9: Edited negative values to positive values | D9: Nergative Values removed

Sheet Analysis sheet
A1: Country | B1: Total Revenue | D1: Country | E1: Number of Transactions | G1: Country | H1: Average revenue | K1: Row Labels | L1: Sum of Revenue | O1: Row Labels | P1: Sum of Revenue | T1: key Insights
A2: {=_xlfn.UNIQUE(Sheet2!$O$2:$O$1021)} -> United Kingdom | B2: =SUMIF(Sheet2!$O$2:$O$1021,A2,Sheet2!$P$2:$P1021) -> 19278.46 | D2: {=_xlfn.UNIQUE(Sheet2!$O$2:$O$1021)} -> United Kingdom | E2: =COUNTIF(Sheet2!$O$2:$O$1021,D2) -> 922 | G2: {=_xlfn.UNIQUE(Sheet2!O2:O1021)} -> United Kingdom | H2: =AVERAGEIF(Sheet2!$O$2:$O$1021,G2,Sheet2!$P$2:$P$1021) -> 20.909393 | K2: United Kingdom | L2: 19278.46 | O2: GOLD WINE GLASS | P2: 1952.64 | T2: The business generated a total revenue of 24,586.40
A3: EIRE | B3: =SUMIF(Sheet2!$O$2:$O$1021,A3,Sheet2!$P$2:$P1022) -> 1155 | D3: EIRE | E3: =COUNTIF(Sheet2!$O$2:$O$1021,D3) -> 19 | G3: EIRE | H3: =AVERAGEIF(Sheet2!$O$2:$O$1021,G3,Sheet2!$P$2:$P$1021) -> 60.789474 | K3: EIRE | L3: 1155 | O3: ASSORTED FARMYARD ANIMALS IN BUCKET | P3: 993.6 | T3: High transaction doesnot mean high average revenue
A4: Germany | B4: =SUMIF(Sheet2!$O$2:$O$1021,A4,Sheet2!$P$2:$P1023) -> 486.5 | D4: Germany | E4: =COUNTIF(Sheet2!$O$2:$O$1021,D4) -> 21 | G4: Germany | H4: =AVERAGEIF(Sheet2!$O$2:$O$1021,G4,Sheet2!$P$2:$P$1021) -> 23.166667 | K4: Denmark | L4: 1083.6 | O4: RUSTIC WOODEN CABINET, GLASS DOORS | P4: 573.92 | T4: Revenue is concentrated among a small group of top performing countries
A5: France | B5: =SUMIF(Sheet2!$O$2:$O$1021,A5,Sheet2!$P$2:$P1024) -> 796.96 | D5: France | E5: =COUNTIF(Sheet2!$O$2:$O$1021,D5) -> 19 | G5: France | H5: =AVERAGEIF(Sheet2!$O$2:$O$1021,G5,Sheet2!$P$2:$P$1021) -> 41.945263 | K5: Netherlands | L5: 872.13 | O5: CHILDS BREAKFAST SET CIRCUS PARADE | P5: 397.8 | T5: Revenue is not evenly distributed among Products
A6: Singapore | B6: =SUMIF(Sheet2!$O$2:$O$1021,A6,Sheet2!$P$2:$P1025) -> 15 | D6: Singapore | E6: =COUNTIF(Sheet2!$O$2:$O$1021,D6) -> 1 | G6: Singapore | H6: =AVERAGEIF(Sheet2!$O$2:$O$1021,G6,Sheet2!$P$2:$P$1021) -> 15 | K6: France | L6: 796.96 | O6: JUMBO SHOPPER VINTAGE RED PAISLEY | P6: 388.5 | T6: A small number of Products contribute a large share of the total revenue
A7: Belgium | B7: =SUMIF(Sheet2!$O$2:$O$1021,A7,Sheet2!$P$2:$P1026) -> 64.5 | D7: Belgium | E7: =COUNTIF(Sheet2!$O$2:$O$1021,D7) -> 2 | G7: Belgium | H7: =AVERAGEIF(Sheet2!$O$2:$O$1021,G7,Sheet2!$P$2:$P$1021) -> 32.25 | K7: Germany | L7: 486.5 | O7: EDWARDIAN PARASOL BLACK | P7: 362.45
A8: Italy | B8: =SUMIF(Sheet2!$O$2:$O$1021,A8,Sheet2!$P$2:$P1027) -> 29.6 | D8: Italy | E8: =COUNTIF(Sheet2!$O$2:$O$1021,D8) -> 2 | G8: Italy | H8: =AVERAGEIF(Sheet2!$O$2:$O$1021,G8,Sheet2!$P$2:$P$1021) -> 14.8 | K8: Portugal | L8: 226.6 | O8: RECIPE BOX WITH METAL HEART | P8: 349.5
A9: RSA | B9: =SUMIF(Sheet2!$O$2:$O$1021,A9,Sheet2!$P$2:$P1028) -> 19.8 | D9: RSA | E9: =COUNTIF(Sheet2!$O$2:$O$1021,D9) -> 1 | G9: RSA | H9: =AVERAGEIF(Sheet2!$O$2:$O$1021,G9,Sheet2!$P$2:$P$1021) -> 19.8 | K9: Sweden | L9: 155.64 | O9: BLUE POLKADOT PUDDING BOWL | P9: 324.48
A10: Denmark | B10: =SUMIF(Sheet2!$O$2:$O$1021,A10,Sheet2!$P$2:$P1029) -> 1083.6 | D10: Denmark | E10: =COUNTIF(Sheet2!$O$2:$O$1021,D10) -> 2 | G10: Denmark | H10: =AVERAGEIF(Sheet2!$O$2:$O$1021,G10,Sheet2!$P$2:$P$1021) -> 541.8 | K10: Japan | L10: 127.5 | O10: SET/10 RED SPOTTY PARTY CANDLES | P10: 305.28 | R10: Product that generated the highest revenue
A11: Netherlands | B11: =SUMIF(Sheet2!$O$2:$O$1021,A11,Sheet2!$P$2:$P1030) -> 872.13 | D11: Netherlands | E11: =COUNTIF(Sheet2!$O$2:$O$1021,D11) -> 5 | G11: Netherlands | H11: =AVERAGEIF(Sheet2!$O$2:$O$1021,G11,Sheet2!$P$2:$P$1021) -> 174.426 | K11: Channel Islands | L11: 68.98 | O11: ROUND SNACK BOXES SET OF 4 FRUITS | P11: 244.8 | R11: Gold wine Glass
A12: Cyprus | B12: =SUMIF(Sheet2!$O$2:$O$1021,A12,Sheet2!$P$2:$P1031) -> 27.6 | D12: Cyprus | E12: =COUNTIF(Sheet2!$O$2:$O$1021,D12) -> 2 | G12: Cyprus | H12: =AVERAGEIF(Sheet2!$O$2:$O$1021,G12,Sheet2!$P$2:$P$1021) -> 13.8 | K12: Belgium | L12: 64.5 | O12: WHITE HANGING HEART T-LIGHT HOLDER | P12: 240.9
A13: USA | B13: =SUMIF(Sheet2!$O$2:$O$1021,A13,Sheet2!$P$2:$P1032) -> 11.8 | D13: USA | E13: =COUNTIF(Sheet2!$O$2:$O$1021,D13) -> 1 | G13: USA | H13: =AVERAGEIF(Sheet2!$O$2:$O$1021,G13,Sheet2!$P$2:$P$1021) -> 11.8 | K13: Greece | L13: 55.98 | O13: HEART OF WICKER LARGE | P13: 237.8
A14: Channel Islands | B14: =SUMIF(Sheet2!$O$2:$O$1021,A14,Sheet2!$P$2:$P1033) -> 68.98 | D14: Channel Islands | E14: =COUNTIF(Sheet2!$O$2:$O$1021,D14) -> 4 | G14: Channel Islands | H14: =AVERAGEIF(Sheet2!$O$2:$O$1021,G14,Sheet2!$P$2:$P$1021) -> 17.245 | K14: Switzerland | L14: 45.6 | O14: RETROSPOT HEART HOT WATER BOTTLE | P14: 204
A15: Portugal | B15: =SUMIF(Sheet2!$O$2:$O$1021,A15,Sheet2!$P$2:$P1034) -> 226.6 | D15: Portugal | E15: =COUNTIF(Sheet2!$O$2:$O$1021,D15) -> 6 | G15: Portugal | H15: =AVERAGEIF(Sheet2!$O$2:$O$1021,G15,Sheet2!$P$2:$P$1021) -> 37.766667 | K15: Spain | L15: 32.7 | O15: JUMBO BAG SCANDINAVIAN PAISLEY | P15: 204
A16: Japan | B16: =SUMIF(Sheet2!$O$2:$O$1021,A16,Sheet2!$P$2:$P1035) -> 127.5 | D16: Japan | E16: =COUNTIF(Sheet2!$O$2:$O$1021,D16) -> 1 | G16: Japan | H16: =AVERAGEIF(Sheet2!$O$2:$O$1021,G16,Sheet2!$P$2:$P$1021) -> 127.5 | K16: Italy | L16: 29.6 | O16: CERAMIC BOWL WITH STRAWBERRY DESIGN | P16: 201.3
A17: Austria | B17: =SUMIF(Sheet2!$O$2:$O$1021,A17,Sheet2!$P$2:$P1036) -> 13.2 | D17: Austria | E17: =COUNTIF(Sheet2!$O$2:$O$1021,D17) -> 1 | G17: Austria | H17: =AVERAGEIF(Sheet2!$O$2:$O$1021,G17,Sheet2!$P$2:$P$1021) -> 13.2 | K17: Cyprus | L17: 27.6 | O17: POLKADOT CUTLERY 24 PCS IN TRAY | P17: 199
A18: Greece | B18: =SUMIF(Sheet2!$O$2:$O$1021,A18,Sheet2!$P$2:$P1037) -> 55.98 | D18: Greece | E18: =COUNTIF(Sheet2!$O$2:$O$1021,D18) -> 3 | G18: Greece | H18: =AVERAGEIF(Sheet2!$O$2:$O$1021,G18,Sheet2!$P$2:$P$1021) -> 18.66 | K18: RSA | L18: 19.8 | O18: WOOD BLACK BOARD ANT WHITE FINISH | P18: 191.25
A19: Switzerland | B19: =SUMIF(Sheet2!$O$2:$O$1021,A19,Sheet2!$P$2:$P1038) -> 45.6 | D19: Switzerland | E19: =COUNTIF(Sheet2!$O$2:$O$1021,D19) -> 2 | G19: Switzerland | H19: =AVERAGEIF(Sheet2!$O$2:$O$1021,G19,Sheet2!$P$2:$P$1021) -> 22.8 | K19: Singapore | L19: 15 | O19: VINTAGE UNION JACK BUNTING | P19: 187
A20: Sweden | B20: =SUMIF(Sheet2!$O$2:$O$1021,A20,Sheet2!$P$2:$P1039) -> 155.64 | D20: Sweden | E20: =COUNTIF(Sheet2!$O$2:$O$1021,D20) -> 2 | G20: Sweden | H20: =AVERAGEIF(Sheet2!$O$2:$O$1021,G20,Sheet2!$P$2:$P$1021) -> 77.82 | K20: Finland | L20: 15 | O20: JUMBO BAG PINK VINTAGE PAISLEY | P20: 184.5
A21: Spain | B21: =SUMIF(Sheet2!$O$2:$O$1021,A21,Sheet2!$P$2:$P1040) -> 32.7 | D21: Spain | E21: =COUNTIF(Sheet2!$O$2:$O$1021,D21) -> 2 | G21: Spain | H21: =AVERAGEIF(Sheet2!$O$2:$O$1021,G21,Sheet2!$P$2:$P$1021) -> 16.35 | K21: Austria | L21: 13.2 | O21: 36 FOIL HEART CAKE CASES | P21: 177.6
A22: Unspecified | B22: =SUMIF(Sheet2!$O$2:$O$1021,A22,Sheet2!$P$2:$P1041) -> 4.25 | D22: Unspecified | E22: =COUNTIF(Sheet2!$O$2:$O$1021,D22) -> 1 | G22: Unspecified | H22: =AVERAGEIF(Sheet2!$O$2:$O$1021,G22,Sheet2!$P$2:$P$1021) -> 4.25 | K22: USA | L22: 11.8 | O22: RETRO SPOT TEA SET CERAMIC 11 PC | P22: 173.25
A23: Finland | B23: =SUMIF(Sheet2!$O$2:$O$1021,A23,Sheet2!$P$2:$P1042) -> 15 | D23: Finland | E23: =COUNTIF(Sheet2!$O$2:$O$1021,D23) -> 1 | G23: Finland | H23: =AVERAGEIF(Sheet2!$O$2:$O$1021,G23,Sheet2!$P$2:$P$1021) -> 15 | K23: Unspecified | L23: 4.25 | O23: BLUE PARTY BAGS | P23: 169
K24: Grand Total | L24: 24586.4 | O24: RED SPOTTY COFFEE MUG | P24: 168
O25: RETRO SPOT TRADITIONAL TEAPOT | P25: 166.8
O26: JUMBO SHOPPER VINTAGE RED PAISLEY | P26: 165
A27: country with the highest total revenue | B27: United Kingdom | D27: country with the highest number of Transactions | E27: United Kingdom | G27: country with the hughest average transaction revenue | H27: Nethelands | K27: Top five country by total revenue | O27: WOODEN BOX OF DOMINOES | P27: 155.14
K28: United Kingdom | O28: HANGING BAUBLE T-LIGHT HOLDER SMALL | P28: 151.2
K29: EIRE | O29: TEA TIME CAKE STAND IN GIFT BOX | P29: 150.5
K30: Denmark | O30: SET/4 WHITE RETRO STORAGE CUBES | P30: 139.8
K31: Netherlands | O31: PLASTERS IN TIN VINTAGE PAISLEY | P31: 139.2
K32: France | O32: HANGING PHOTO CLIP ROPE LADDER | P32: 139.2
K33: Germany | O33: CINAMMON & ORANGE WREATH | P33: 138.3
O34: MAGIC DRAWING SLATE DOLLY GIRL | P34: 138.24
O35: ASSORTED COLOUR BIRD ORNAMENT | P35: 136.89
O36: WOODLAND STORAGE BOX SMALL | P36: 132.6
O37: WHITE CHERRY LIGHTS | P37: 130.8
O38: PARTY BUNTING | P38: 130.2
O39: REGENCY CAKESTAND 3 TIER | P39: 127.5
O40: STRAWBERRY PICNIC BAG | P40: 127.5
...
