Workbook

Sheet Customer_Master
A1: CustomerID | B1: CustomerName | C1: Country
A2: 12346 | B2: Customer 12346 | C2: United Kingdom
A3: 12347 | B3: Customer 12347 | C3: Iceland
A4: 12356 | B4: Customer 12356 | C4: Portugal
A5: 12359 | B5: Customer 12359 | C5: Cyprus
A6: 12369 | B6: Customer 12369 | C6: Austria
A7: 12377 | B7: Customer 12377 | C7: Switzerland
A8: 12380 | B8: Customer 12380 | C8: Belgium
A9: 12388 | B9: Customer 12388 | C9: Australia
A10: 12389 | B10: Customer 12389 | C10: Australia
A11: 12391 | B11: Customer 12391 | C11: Cyprus
A12: 12393 | B12: Customer 12393 | C12: Australia
A13: 12395 | B13: Customer 12395 | C13: Belgium
... A2012: 18287 | B2012: Customer 18287 | C2012: United Kingdom

Sheet Sheet3
A3: Row Labels | B3: Sum of TotalSales | C3: Sum of TotalSales2 | W3: Row Labels | X3: Sum of TotalSales
A4: United Kingdom | B4: 86048.33 | C4: 0.83455542 | D4: Row Labels | E4: Sum of TotalSales | F4: Sum of Quantity | W4: 18102 | X4: 4581.2
A5: Netherlands | B5: 4090.88 | C5: 0.039676145 | D5: ASSORTED FARMYARD ANIMALS IN BUCKET | E5: 993.6 | F5: 3312 | H5: Row Labels | I5: Sum of TotalSales | W5: Customer 18102 | X5: 4581.2
A6: EIRE | B6: 3734.27 | C6: 0.036217498 | D6: WHITE HANGING HEART T-LIGHT HOLDER | E6: 2849.4 | F6: 1076 | H6: 2009 | I6: 8326.03 | W6: 17450 | X6: 3879.96
A7: Germany | B7: 2538.06 | C7: 0.024615838 | D7: VINTAGE UNION JACK DOORSTOP | E7: 3873.98 | F7: 650 | H7: Dec | I7: 8326.03 | W7: Customer 17450 | X7: 3879.96
A8: France | B8: 1558.98 | C8: 0.015120052 | D8: RED/WHITE DOTS RUFFLED UMBRELLA | E8: 1829.1 | F8: 594 | H8: 2010 | I8: 94780.76 | W8: 14646 | X8: 3807.22
A9: Denmark | B9: 1100.1 | C9: 0.01066952 | D9: JUMBO BAG RED RETROSPOT | E9: 828.45 | F9: 471 | H9: Jan | I9: 4982.33 | W9: Customer 14646 | X9: 3807.22
A10: Switzerland | B10: 444.06 | C10: 0.0043067969 | D10: DOORMAT AIRMAIL | E10: 1583.7 | F10: 330 | H10: Feb | I10: 6751.77 | W10: 15061 | X10: 2245.84
A11: Greece | B11: 420.04 | C11: 0.0040738345 | D11: HOME SWEET HOME METAL SIGN | E11: 752.1 | F11: 294 | H11: Mar | I11: 7871.57 | W11: Customer 15061 | X11: 2245.84
A12: Sweden | B12: 392.52 | C12: 0.0038069268 | D12: PAPER CHAIN KIT 50'S CHRISTMAS | E12: 756.55 | F12: 289 | H12: Apr | I12: 4977.62 | W12: 17511 | X12: 2090.18
A13: Portugal | B13: 327.85 | C13: 0.003179713 | D13: GOLD WINE GLASS | E13: 976.32 | F13: 288 | H13: May | I13: 8370.13 | W13: Customer 17511 | X13: 2090.18
A14: Channel Islands | B14: 262.61 | C14: 0.002546971 | D14: REGENCY CAKESTAND 3 TIER | E14: 1032.15 | F14: 89 | H14: Jun | I14: 4302.51 | W14: 14911 | X14: 2004.28
A15: United Arab Emirates | B15: 253 | C15: 0.0024537666 | D15: Grand Total | E15: 15475.35 | F15: 7393 | H15: Jul | I15: 7793.4 | W15: Customer 14911 | X15: 2004.28
A16: Finland | B16: 249.4 | C16: 0.0024188514 | H16: Aug | I16: 7010.15 | W16: 16013 | X16: 1756
A17: Belgium | B17: 227.8 | C17: 0.0022093598 | H17: Sep | I17: 13351.69 | W17: Customer 16013 | X17: 1756
A18: Spain | B18: 212.9 | C18: 0.0020648495 | H18: Oct | I18: 11672.35 | W18: 14156 | X18: 1692.19
A19: Japan | B19: 200.15 | C19: 0.0019411913 | H19: Nov | I19: 13728.1 | W19: Customer 14156 | X19: 1692.19
A20: Australia | B20: 149.4 | C20: 0.0014489831 | H20: Dec | I20: 3969.14 | W20: 13694 | X20: 1173.8
A21: Cyprus | B21: 143.6 | C21: 0.0013927308 | H21: Grand Total | I21: 103106.79 | W21: Customer 13694 | X21: 1173.8
A22: Not Found | B22: 128.5 | C22: 0.0012462807 | W22: 13089 | X22: 1034.17
A23: Italy | B23: 123 | C23: 0.0011929379 | W23: Customer 13089 | X23: 1034.17
A24: Thailand | B24: 120.96 | C24: 0.0011731526 | W24: 13902 | X24: 993.6
A25: Austria | B25: 86.44 | C25: 0.0008383541 | W25: Customer 13902 | X25: 993.6
A26: Unspecified | B26: 69.95 | C26: 0.00067842283 | W26: 16422 | X26: 953.64
A27: Norway | B27: 67.74 | C27: 0.00065698874 | W27: Customer 16422 | X27: 953.64
A28: Singapore | B28: 52.5 | C28: 0.00050918082 | W28: 15311 | X28: 895.42
A29: Malta | B29: 41.55 | C29: 0.00040298025 | W29: Customer 15311 | X29: 895.42
A30: USA | B30: 25 | C30: 0.00024246706 | W30: 13881 | X30: 753.26
A31: RSA | B31: 19.8 | C31: 0.00019203391 | W31: Customer 13881 | X31: 753.26
A32: Iceland | B32: 10.2 | C32: 9.892656e-05 | W32: 16684 | X32: 628.56
A33: Korea | B33: 7.2 | C33: 6.9830513e-05 | W33: Customer 16684 | X33: 628.56
A34: Grand Total | B34: 103106.79 | C34: 1 | W34: 13802 | X34: 600.62
W35: Customer 13802 | X35: 600.62
W36: 12931 | X36: 574.5
W37: Customer 12931 | X37: 574.5
W38: 12678 | X38: 571.2
W39: Customer 12678 | X39: 571.2
W40: 14062 | X40: 550.8
W41: Customer 14062 | X41: 550.8
W42: 13090 | X42: 492.15
...

Sheet Transactions
A1: TransactionID | B1: Invoice | C1: StockCode | D1: Description | E1: InvoiceDate | F1: CustomerID | G1: Country | H1: CustomerName | I1: CustomerCountry | J1: Price | K1: Quantity | L1: TotalSales
A2: 1 | B2: 489439 | C2: 85216 | D2: ASSORTED CAKES FRIDGE MAGNETS | E2: 40148.394 | F2: C99991 | G2: France | H2: =_xlfn.XLOOKUP(F2,Customer_Master!$A:$A,Customer_Master!$B:$B,"Not Found") -> Not Found | I2: =_xlfn.XLOOKUP(F2,Customer_Master!$A:$A,Customer_Master!$C:$C,"Not Found") -> Not Found | J2: 0.65 | K2: 12 | L2: =PRODUCT(J2:K2) -> 7.8
A3: 2 | B3: 489439 | C3: 21731 | D3: RED TOADSTOOL LED NIGHT LIGHT | E3: 40148.394 | F3: C99992 | G3: France | H3: =_xlfn.XLOOKUP(F3,Customer_Master!$A:$A,Customer_Master!$B:$B,"Not Found") -> Not Found | I3: =_xlfn.XLOOKUP(F3,Customer_Master!$A:$A,Customer_Master!$C:$C,"Not Found") -> Not Found | J3: 1.65 | K3: 24 | L3: =PRODUCT(J3:K3) -> 39.6
A4: 3 | B4: 489443 | C4: 82580 | D4: BATHROOM METAL SIGN | E4: 40148.41 | F4: C99993 | G4: United Kingdom | H4: =_xlfn.XLOOKUP(F4,Customer_Master!$A:$A,Customer_Master!$B:$B,"Not Found") -> Not Found | I4: =_xlfn.XLOOKUP(F4,Customer_Master!$A:$A,Customer_Master!$C:$C,"Not Found") -> Not Found | J4: 0.55 | K4: 12 | L4: =PRODUCT(J4:K4) -> 6.6
A5: 4 | B5: 489488 | C5: 84997C | D5: BLUE 3 PIECE MINI DOTS CUTLERY SET | E5: 40148.458 | F5: C99994 | G5: United Kingdom | H5: =_xlfn.XLOOKUP(F5,Customer_Master!$A:$A,Customer_Master!$B:$B,"Not Found") -> Not Found | I5: =_xlfn.XLOOKUP(F5,Customer_Master!$A:$A,Customer_Master!$C:$C,"Not Found") -> Not Found | J5: 3.75 | K5: 4 | L5: =PRODUCT(J5:K5) -> 15
A6: 5 | B6: 489514 | C6: 21955 | D6: UNION JACK GUNS & ROSES DOORMAT | E6: 40148.473 | F6: C99995 | G6: United Kingdom | H6: =_xlfn.XLOOKUP(F6,Customer_Master!$A:$A,Customer_Master!$B:$B,"Not Found") -> Not Found | I6: =_xlfn.XLOOKUP(F6,Customer_Master!$A:$A,Customer_Master!$C:$C,"Not Found") -> Not Found | J6: 5.95 | K6: 10 | L6: =PRODUCT(J6:K6) -> 59.5
A7: 6 | B7: 489517 | C7: 21791 | D7: VINTAGE HEADS AND TAILS CARD GAME | E7: 40148.482 | F7: 16329 | G7: United Kingdom | H7: =_xlfn.XLOOKUP(F7,Customer_Master!$A:$A,Customer_Master!$B:$B,"Not Found") -> Customer 16329 | I7: =_xlfn.XLOOKUP(F7,Customer_Master!$A:$A,Customer_Master!$C:$C,"Not Found") -> United Kingdom | J7: 1.25 | K7: 6 | L7: =PRODUCT(J7:K7) -> 7.5
A8: 7 | B8: 489517 | C8: 22130 | D8: PARTY CONE CHRISTMAS DECORATION | E8: 40148.482 | F8: 16329 | G8: United Kingdom | H8: =_xlfn.XLOOKUP(F8,Customer_Master!$A:$A,Customer_Master!$B:$B,"Not Found") -> Customer 16329 | I8: =_xlfn.XLOOKUP(F8,Customer_Master!$A:$A,Customer_Master!$C:$C,"Not Found") -> United Kingdom | J8: 0.85 | K8: 6 | L8: =PRODUCT(J8:K8) -> 5.1
A9: 8 | B9: 489522 | C9: 21869 | D9: POTTING SHED COFFEE MUG | E9: 40148.49 | F9: 15998 | G9: United Kingdom | H9: =_xlfn.XLOOKUP(F9,Customer_Master!$A:$A,Customer_Master!$B:$B,"Not Found") -> Customer 15998 | I9: =_xlfn.XLOOKUP(F9,Customer_Master!$A:$A,Customer_Master!$C:$C,"Not Found") -> United Kingdom | J9: 1.25 | K9: 1 | L9: =PRODUCT(J9:K9) -> 1.25
A10: 9 | B10: 489529 | C10: 22036 | D10: DINOSAUR BIRTHDAY CARD | E10: 40148.494 | F10: 17984 | G10: United Kingdom | H10: =_xlfn.XLOOKUP(F10,Customer_Master!$A:$A,Customer_Master!$B:$B,"Not Found") -> Customer 17984 | I10: =_xlfn.XLOOKUP(F10,Customer_Master!$A:$A,Customer_Master!$C:$C,"Not Found") -> United Kingdom | J10: 0.42 | K10: 12 | L10: =PRODUCT(J10:K10) -> 5.04
A11: 10 | B11: 489532 | C11: 84990 | D11: 60 GOLD AND SILVER FAIRY CAKE CASES | E11: 40148.499 | F11: 13394 | G11: United Kingdom | H11: =_xlfn.XLOOKUP(F11,Customer_Master!$A:$A,Customer_Master!$B:$B,"Not Found") -> Customer 13394 | I11: =_xlfn.XLOOKUP(F11,Customer_Master!$A:$A,Customer_Master!$C:$C,"Not Found") -> United Kingdom | J11: 0.55 | K11: 24 | L11: =PRODUCT(J11:K11) -> 13.2
A12: 11 | B12: 489536 | C12: 21890 | D12: S/6 WOODEN SKITTLES IN COTTON BAG | E12: 40148.509 | F12: 16393 | G12: United Kingdom | H12: =_xlfn.XLOOKUP(F12,Customer_Master!$A:$A,Customer_Master!$B:$B,"Not Found") -> Customer 16393 | I12: =_xlfn.XLOOKUP(F12,Customer_Master!$A:$A,Customer_Master!$C:$C,"Not Found") -> United Kingdom | J12: 2.95 | K12: 1 | L12: =PRODUCT(J12:K12) -> 2.95
A13: 12 | B13: 489536 | C13: 22174 | D13: PHOTO CUBE | E13: 40148.509 | F13: 16393 | G13: United Kingdom | H13: =_xlfn.XLOOKUP(F13,Customer_Master!$A:$A,Customer_Master!$B:$B,"Not Found") -> Customer 16393 | I13: =_xlfn.XLOOKUP(F13,Customer_Master!$A:$A,Customer_Master!$C:$C,"Not Found") -> United Kingdom | J13: 1.65 | K13: 2 | L13: =PRODUCT(J13:K13) -> 3.3
A14: 13 | B14: 489536 | C14: 21581 | D14: SKULLS DESIGN COTTON TOTE BAG | E14: 40148.509 | F14: 16393 | G14: United Kingdom | H14: =_xlfn.XLOOKUP(F14,Customer_Master!$A:$A,Customer_Master!$B:$B,"Not Found") -> Customer 16393 | I14: =_xlfn.XLOOKUP(F14,Customer_Master!$A:$A,Customer_Master!$C:$C,"Not Found") -> United Kingdom | J14: 2.25 | K14: 4 | L14: =PRODUCT(J14:K14) -> 9
A15: 14 | B15: 489537 | C15: 48188 | D15: DOOR MAT WELCOME PUPPIES | E15: 40148.51 | F15: 14040 | G15: United Kingdom | H15: =_xlfn.XLOOKUP(F15,Customer_Master!$A:$A,Customer_Master!$B:$B,"Not Found") -> Customer 14040 | I15: =_xlfn.XLOOKUP(F15,Customer_Master!$A:$A,Customer_Master!$C:$C,"Not Found") -> United Kingdom | J15: 6.75 | K15: 2 | L15: =PRODUCT(J15:K15) -> 13.5
A16: 15 | B16: 489537 | C16: 72800F | D16: 4 IVORY DINNER CANDLES GOLD FLOCK | E16: 40148.51 | F16: 14040 | G16: United Kingdom | H16: =_xlfn.XLOOKUP(F16,Customer_Master!$A:$A,Customer_Master!$B:$B,"Not Found") -> Customer 14040 | I16: =_xlfn.XLOOKUP(F16,Customer_Master!$A:$A,Customer_Master!$C:$C,"Not Found") -> United Kingdom | J16: 2.55 | K16: 1 | L16: =PRODUCT(J16:K16) -> 2.55
A17: 16 | B17: 489539 | C17: 22086 | D17: PAPER CHAIN KIT 50'S CHRISTMAS | E17: 40148.512 | F17: 15061 | G17: United Kingdom | H17: =_xlfn.XLOOKUP(F17,Customer_Master!$A:$A,Customer_Master!$B:$B,"Not Found") -> Customer 15061 | I17: =_xlfn.XLOOKUP(F17,Customer_Master!$A:$A,Customer_Master!$C:$C,"Not Found") -> United Kingdom | J17: 2.55 | K17: 160 | L17: =PRODUCT(J17:K17) -> 408
A18: 17 | B18: 489560 | C18: 21034 | D18: REX CASH+CARRY JUMBO SHOPPER | E18: 40148.539 | F18: 13526 | G18: United Kingdom | H18: =_xlfn.XLOOKUP(F18,Customer_Master!$A:$A,Customer_Master!$B:$B,"Not Found") -> Customer 13526 | I18: =_xlfn.XLOOKUP(F18,Customer_Master!$A:$A,Customer_Master!$C:$C,"Not Found") -> United Kingdom | J18: 0.95 | K18: 3 | L18: =PRODUCT(J18:K18) -> 2.85
A19: 18 | B19: 489562 | C19: 22139 | D19: RETRO SPOT TEA SET CERAMIC 11 PC | E19: 40148.547 | F19: 17998 | G19: United Kingdom | H19: =_xlfn.XLOOKUP(F19,Customer_Master!$A:$A,Customer_Master!$B:$B,"Not Found") -> Customer 17998 | I19: =_xlfn.XLOOKUP(F19,Customer_Master!$A:$A,Customer_Master!$C:$C,"Not Found") -> United Kingdom | J19: 4.95 | K19: 1 | L19: =PRODUCT(J19:K19) -> 4.95
A20: 19 | B20: 489571 | C20: 79323W | D20: WHITE CHERRY LIGHTS | E20: 40148.562 | F20: 15967 | G20: United Kingdom | H20: =_xlfn.XLOOKUP(F20,Customer_Master!$A:$A,Customer_Master!$B:$B,"Not Found") -> Customer 15967 | I20: =_xlfn.XLOOKUP(F20,Customer_Master!$A:$A,Customer_Master!$C:$C,"Not Found") -> United Kingdom | J20: 6.75 | K20: 1 | L20: =PRODUCT(J20:K20) -> 6.75
A21: 20 | B21: 489572 | C21: 37444C | D21: PINK BREAKFAST CUP AND SAUCER | E21: 40148.562 | F21: 17611 | G21: United Kingdom | H21: =_xlfn.XLOOKUP(F21,Customer_Master!$A:$A,Customer_Master!$B:$B,"Not Found") -> Customer 17611 | I21: =_xlfn.XLOOKUP(F21,Customer_Master!$A:$A,Customer_Master!$C:$C,"Not Found") -> United Kingdom | J21: 2.95 | K21: 2 | L21: =PRODUCT(J21:K21) -> 5.9
A22: 21 | B22: 489574 | C22: 21893 | D22: POTTING SHED SEED TIN | E22: 40148.563 | F22: 13097 | G22: United Kingdom | H22: =_xlfn.XLOOKUP(F22,Customer_Master!$A:$A,Customer_Master!$B:$B,"Not Found") -> Customer 13097 | I22: =_xlfn.XLOOKUP(F22,Customer_Master!$A:$A,Customer_Master!$C:$C,"Not Found") -> United Kingdom | J22: 4.25 | K22: 3 | L22: =PRODUCT(J22:K22) -> 12.75
A23: 22 | B23: 489594 | C23: 22055 | D23: MINI CAKE STAND HANGING STRAWBERY | E23: 40148.597 | F23: 15005 | G23: United Kingdom | H23: =_xlfn.XLOOKUP(F23,Customer_Master!$A:$A,Customer_Master!$B:$B,"Not Found") -> Customer 15005 | I23: =_xlfn.XLOOKUP(F23,Customer_Master!$A:$A,Customer_Master!$C:$C,"Not Found") -> United Kingdom | J23: 1.65 | K23: 2 | L23: =PRODUCT(J23:K23) -> 3.3
A24: 23 | B24: 489640 | C24: 22172 | D24: METAL SHELF WITH RAIL | E24: 40148.678 | F24: 17345 | G24: United Kingdom | H24: =_xlfn.XLOOKUP(F24,Customer_Master!$A:$A,Customer_Master!$B:$B,"Not Found") -> Customer 17345 | I24: =_xlfn.XLOOKUP(F24,Customer_Master!$A:$A,Customer_Master!$C:$C,"Not Found") -> United Kingdom | J24: 8.5 | K24: 1 | L24: =PRODUCT(J24:K24) -> 8.5
A25: 24 | B25: 489641 | C25: 79323W | D25: WHITE CHERRY LIGHTS | E25: 40148.679 | F25: 13819 | G25: United Kingdom | H25: =_xlfn.XLOOKUP(F25,Customer_Master!$A:$A,Customer_Master!$B:$B,"Not Found") -> Customer 13819 | I25: =_xlfn.XLOOKUP(F25,Customer_Master!$A:$A,Customer_Master!$C:$C,"Not Found") -> United Kingdom | J25: 6.75 | K25: 4 | L25: =PRODUCT(J25:K25) -> 27
A26: 25 | B26: 489674 | C26: 84970S | D26: HANGING HEART ZINC T-LIGHT HOLDER | E26: 40149.399 | F26: 15602 | G26: United Kingdom | H26: =_xlfn.XLOOKUP(F26,Customer_Master!$A:$A,Customer_Master!$B:$B,"Not Found") -> Customer 15602 | I26: =_xlfn.XLOOKUP(F26,Customer_Master!$A:$A,Customer_Master!$C:$C,"Not Found") -> United Kingdom | J26: 0.85 | K26: 12 | L26: =PRODUCT(J26:K26) -> 10.2
A27: 26 | B27: 489679 | C27: 22322 | D27: BIRD DECORATION GREEN SPOT | E27: 40149.417 | F27: 16163 | G27: United Kingdom | H27: =_xlfn.XLOOKUP(F27,Customer_Master!$A:$A,Customer_Master!$B:$B,"Not Found") -> Customer 16163 | I27: =_xlfn.XLOOKUP(F27,Customer_Master!$A:$A,Customer_Master!$C:$C,"Not Found") -> United Kingdom | J27: 0.85 | K27: 12 | L27: =PRODUCT(J27:K27) -> 10.2
A28: 27 | B28: 489683 | C28: 84970L | D28: SINGLE HEART ZINC T-LIGHT HOLDER | E28: 40149.423 | F28: 16131 | G28: United Kingdom | H28: =_xlfn.XLOOKUP(F28,Customer_Master!$A:$A,Customer_Master!$B:$B,"Not Found") -> Customer 16131 | I28: =_xlfn.XLOOKUP(F28,Customer_Master!$A:$A,Customer_Master!$C:$C,"Not Found") -> United Kingdom | J28: 0.95 | K28: 24 | L28: =PRODUCT(J28:K28) -> 22.8
A29: 28 | B29: 489684 | C29: 22215 | D29: CAKE STAND WHITE TWO TIER LACE | E29: 40149.427 | F29: 14560 | G29: United Kingdom | H29: =_xlfn.XLOOKUP(F29,Customer_Master!$A:$A,Customer_Master!$B:$B,"Not Found") -> Customer 14560 | I29: =_xlfn.XLOOKUP(F29,Customer_Master!$A:$A,Customer_Master!$C:$C,"Not Found") -> United Kingdom | J29: 8.5 | K29: 2 | L29: =PRODUCT(J29:K29) -> 17
A30: 29 | B30: 489765 | C30: 84854 | D30: GIRLY PINK TOOL SET | E30: 40149.481 | F30: 15353 | G30: United Kingdom | H30: =_xlfn.XLOOKUP(F30,Customer_Master!$A:$A,Customer_Master!$B:$B,"Not Found") -> Customer 15353 | I30: =_xlfn.XLOOKUP(F30,Customer_Master!$A:$A,Customer_Master!$C:$C,"Not Found") -> United Kingdom | J30: 4.95 | K30: 1 | L30: =PRODUCT(J30:K30) -> 4.95
A31: 30 | B31: 489785 | C31: 85066 | D31: CREAM SWEETHEART MINI CHEST | E31: 40149.494 | F31: 14653 | G31: United Kingdom | H31: =_xlfn.XLOOKUP(F31,Customer_Master!$A:$A,Customer_Master!$B:$B,"Not Found") -> Customer 14653 | I31: =_xlfn.XLOOKUP(F31,Customer_Master!$A:$A,Customer_Master!$C:$C,"Not Found") -> United Kingdom | J31: 12.75 | K31: 2 | L31: =PRODUCT(J31:K31) -> 25.5
A32: 31 | B32: 489795 | C32: 22189 | D32: CREAM HEART CARD HOLDER | E32: 40149.509 | F32: 14440 | G32: United Kingdom | H32: =_xlfn.XLOOKUP(F32,Customer_Master!$A:$A,Customer_Master!$B:$B,"Not Found") -> Customer 14440 | I32: =_xlfn.XLOOKUP(F32,Customer_Master!$A:$A,Customer_Master!$C:$C,"Not Found") -> United Kingdom | J32: 3.95 | K32: 12 | L32: =PRODUCT(J32:K32) -> 47.4
A33: 32 | B33: 489802 | C33: 85104 | D33: SILVER GLASS T-LIGHT SET | E33: 40149.522 | F33: 15581 | G33: United Kingdom | H33: =_xlfn.XLOOKUP(F33,Customer_Master!$A:$A,Customer_Master!$B:$B,"Not Found") -> Customer 15581 | I33: =_xlfn.XLOOKUP(F33,Customer_Master!$A:$A,Customer_Master!$C:$C,"Not Found") -> United Kingdom | J33: 2.95 | K33: 4 | L33: =PRODUCT(J33:K33) -> 11.8
A34: 33 | B34: 489805 | C34: 84600 | D34: NEW BAROQUE JEWELLERY BOX | E34: 40149.527 | F34: 17377 | G34: United Kingdom | H34: =_xlfn.XLOOKUP(F34,Customer_Master!$A:$A,Customer_Master!$B:$B,"Not Found") -> Customer 17377 | I34: =_xlfn.XLOOKUP(F34,Customer_Master!$A:$A,Customer_Master!$C:$C,"Not Found") -> United Kingdom | J34: 7.95 | K34: 1 | L34: =PRODUCT(J34:K34) -> 7.95
A35: 34 | B35: 489811 | C35: 21622 | D35: VINTAGE UNION JACK CUSHION COVER | E35: 40149.537 | F35: 16210 | G35: United Kingdom | H35: =_xlfn.XLOOKUP(F35,Customer_Master!$A:$A,Customer_Master!$B:$B,"Not Found") -> Customer 16210 | I35: =_xlfn.XLOOKUP(F35,Customer_Master!$A:$A,Customer_Master!$C:$C,"Not Found") -> United Kingdom | J35: 4.95 | K35: 4 | L35: =PRODUCT(J35:K35) -> 19.8
A36: 35 | B36: C489813 | C36: 84472 | D36: PINK AND LILAC QUILTED THROW | E36: 40149.543 | F36: 17867 | G36: United Kingdom | H36: =_xlfn.XLOOKUP(F36,Customer_Master!$A:$A,Customer_Master!$B:$B,"Not Found") -> Customer 17867 | I36: =_xlfn.XLOOKUP(F36,Customer_Master!$A:$A,Customer_Master!$C:$C,"Not Found") -> United Kingdom | J36: 45.95 | K36: -1 | L36: =PRODUCT(J36:K36) -> -45.95
A37: 36 | B37: 489814 | C37: 84270 | D37: ASSTD DESIGN BUBBLE GUM RING | E37: 40149.546 | F37: 14669 | G37: United Kingdom | H37: =_xlfn.XLOOKUP(F37,Customer_Master!$A:$A,Customer_Master!$B:$B,"Not Found") -> Customer 14669 | I37: =_xlfn.XLOOKUP(F37,Customer_Master!$A:$A,Customer_Master!$C:$C,"Not Found") -> United Kingdom | J37: 0.21 | K37: 30 | L37: =PRODUCT(J37:K37) -> 6.3
A38: 37 | B38: 489817 | C38: 22218 | D38: CAKE STAND LACE WHITE | E38: 40149.557 | F38: 16711 | G38: United Kingdom | H38: =_xlfn.XLOOKUP(F38,Customer_Master!$A:$A,Customer_Master!$B:$B,"Not Found") -> Customer 16711 | I38: =_xlfn.XLOOKUP(F38,Customer_Master!$A:$A,Customer_Master!$C:$C,"Not Found") -> United Kingdom | J38: 3.75 | K38: 24 | L38: =PRODUCT(J38:K38) -> 90
A39: 38 | B39: 489822 | C39: 84874B | D39: BLUE TRAVEL FIRST AID KIT | E39: 40149.56 | F39: 14204 | G39: United Kingdom | H39: =_xlfn.XLOOKUP(F39,Customer_Master!$A:$A,Customer_Master!$B:$B,"Not Found") -> Customer 14204 | I39: =_xlfn.XLOOKUP(F39,Customer_Master!$A:$A,Customer_Master!$C:$C,"Not Found") -> United Kingdom | J39: 1.65 | K39: 1 | L39: =PRODUCT(J39:K39) -> 1.65
A40: 39 | B40: 489824 | C40: 20982 | D40: 12 PENCILS TALL TUBE SKULLS | E40: 40149.565 | F40: 16797 | G40: United Kingdom | H40: =_xlfn.XLOOKUP(F40,Customer_Master!$A:$A,Customer_Master!$B:$B,"Not Found") -> Customer 16797 | I40: =_xlfn.XLOOKUP(F40,Customer_Master!$A:$A,Customer_Master!$C:$C,"Not Found") -> United Kingdom | J40: 0.85 | K40: 2 | L40: =PRODUCT(J40:K40) -> 1.7
...
